<?xml version="1.0" encoding="UTF-8"?>
<!-- Generated by org.testng.reporters.JUnitReportReporter -->
<testsuite hostname="thunderdome" name="com.bility.test.sanityTests.TestB" tests="5" failures="1" timestamp="4 Feb 2016 11:11:21 GMT" time="8.516" errors="0">
  <testcase name="fifthTestCaseB" time="2.006" classname="com.bility.test.sanityTests.TestB"/>
  <testcase name="firstTestCaseB" time="2.005" classname="com.bility.test.sanityTests.TestB"/>
  <testcase name="thirdTestCaseB" time="2.001" classname="com.bility.test.sanityTests.TestB"/>
  <testcase name="secondTestCaseB" time="0.503" classname="com.bility.test.sanityTests.TestB">
    <failure type="java.lang.AssertionError" message="Failing this Test">
      <![CDATA[java.lang.AssertionError: Failing this Test
	at org.testng.Assert.fail(Assert.java:94)
	at com.bility.test.sanityTests.TestB.secondTestCaseB(TestB.java:24)
	at sun.reflect.NativeMethodAccessorImpl.invoke0(Native Method)
	at sun.reflect.NativeMethodAccessorImpl.invoke(NativeMethodAccessorImpl.java:62)
	at sun.reflect.DelegatingMethodAccessorImpl.invoke(DelegatingMethodAccessorImpl.java:43)
	at java.lang.reflect.Method.invoke(Method.java:497)
	at org.testng.internal.MethodInvocationHelper.invokeMethod(MethodInvocationHelper.java:86)
	at org.testng.internal.Invoker.invokeMethod(Invoker.java:643)
	at org.testng.internal.Invoker.invokeTestMethod(Invoker.java:820)
	at org.testng.internal.Invoker.invokeTestMethods(Invoker.java:1128)
	at org.testng.internal.TestMethodWorker.invokeTestMethods(TestMethodWorker.java:129)
	at org.testng.internal.TestMethodWorker.run(TestMethodWorker.java:112)
	at java.util.concurrent.ThreadPoolExecutor.runWorker(ThreadPoolExecutor.java:1142)
	at java.util.concurrent.ThreadPoolExecutor$Worker.run(ThreadPoolExecutor.java:617)
	at java.lang.Thread.run(Thread.java:745)
]]>
    </failure>
  </testcase> <!-- secondTestCaseB -->
  <testcase name="fourthTestCaseB" time="2.001" classname="com.bility.test.sanityTests.TestB"/>
</testsuite> <!-- com.bility.test.sanityTests.TestB -->
